<sdf version='1.7'>
  <world name='default'>
    <light name='sun' type='directional'>
      <cast_shadows>1</cast_shadows>
      <pose>0 0 10 0 -0 0</pose>
      <diffuse>0.8 0.8 0.8 1</diffuse>
      <specular>0.2 0.2 0.2 1</specular>
      <attenuation>
        <range>1000</range>
        <constant>0.9</constant>
        <linear>0.01</linear>
        <quadratic>0.001</quadratic>
      </attenuation>
      <direction>-0.5 0.1 -0.9</direction>
      <spot>
        <inner_angle>0</inner_angle>
        <outer_angle>0</outer_angle>
        <falloff>0</falloff>
      </spot>
    </light>
    <model name='ground_plane'>
      <static>1</static>
      <link name='link'>
        <collision name='collision'>
          <geometry>
            <plane>
              <normal>0 0 1</normal>
              <size>100 100</size>
            </plane>
          </geometry>
          <surface>
            <contact>
              <collide_bitmask>65535</collide_bitmask>
              <ode/>
            </contact>
            <friction>
              <ode>
                <mu>100</mu>
                <mu2>50</mu2>
              </ode>
              <torsional>
                <ode/>
              </torsional>
            </friction>
            <bounce/>
          </surface>
          <max_contacts>10</max_contacts>
        </collision>
        <visual name='visual'>
          <cast_shadows>0</cast_shadows>
          <geometry>
            <plane>
              <normal>0 0 1</normal>
              <size>100 100</size>
            </plane>
          </geometry>
          <material>
            <script>
              <uri>file://media/materials/scripts/gazebo.material</uri>
              <name>Gazebo/Grey</name>
            </script>
          </material>
        </visual>
        <self_collide>0</self_collide>
        <enable_wind>0</enable_wind>
        <kinematic>0</kinematic>
      </link>
    </model>
    <gravity>0 0 -9.8</gravity>
    <magnetic_field>6e-06 2.3e-05 -4.2e-05</magnetic_field>
    <atmosphere type='adiabatic'/>
    <physics type='ode'>
      <max_step_size>0.001</max_step_size>
      <real_time_factor>1</real_time_factor>
      <real_time_update_rate>1000</real_time_update_rate>
    </physics>
    <scene>
      <ambient>0.4 0.4 0.4 1</ambient>
      <background>0.7 0.7 0.7 1</background>
      <shadows>1</shadows>
    </scene>
    <wind/>
    <spherical_coordinates>
      <surface_model>EARTH_WGS84</surface_model>
      <latitude_deg>0</latitude_deg>
      <longitude_deg>0</longitude_deg>
      <elevation>0</elevation>
      <heading_deg>0</heading_deg>
    </spherical_coordinates>
    <model name='rover'>
      <link name='base_footprint'>
        <inertial>
          <pose>0.00061 0 0.256818 0 -0 0</pose>
          <mass>5.445</mass>
          <inertia>
            <ixx>0.00716592</ixx>
            <ixy>0</ixy>
            <ixz>-0.00170026</ixz>
            <iyy>0.0097681</iyy>
            <iyz>0</iyz>
            <izz>0.00672218</izz>
          </inertia>
        </inertial>
        <collision name='base_footprint_fixed_joint_lump__base_link_collision'>
          <pose>0 0 0.271 0 -0 3.14159</pose>
          <geometry>
            <box>
              <size>0.228 0.178 0.102</size>
            </box>
          </geometry>
          <surface>
            <contact>
              <ode/>
            </contact>
            <friction>
              <ode/>
              <torsional>
                <ode/>
              </torsional>
            </friction>
            <bounce/>
          </surface>
          <max_contacts>10</max_contacts>
        </collision>
        <collision name='base_footprint_fixed_joint_lump__camera_link_collision_1'>
          <pose>0.114 0 0.27 0 -0 3.14159</pose>
          <geometry>
            <box>
              <size>0.03 0.03 0.03</size>
            </box>
          </geometry>
          <surface>
            <contact>
              <ode/>
            </contact>
            <friction>
              <ode/>
              <torsional>
                <ode/>
              </torsional>
            </friction>
            <bounce/>
          </surface>
          <max_contacts>10</max_contacts>
        </collision>
        <collision name='base_footprint_fixed_joint_lump__depth_camera_mount_collision_2'>
          <pose>0 0 0.447 0 -0 0</pose>
          <geometry>
            <cylinder>
              <length>0.25</length>
              <radius>0.02</radius>
            </cylinder>
          </geometry>
          <max_contacts>10</max_contacts>
          <surface>
            <contact>
              <ode/>
            </contact>
            <bounce/>
            <friction>
              <torsional>
                <ode/>
              </torsional>
              <ode/>
            </friction>
          </surface>
        </collision>
        <collision name='base_footprint_fixed_joint_lump__depth_camera_link_collision_3'>
          <pose>-0.001 0 0.606 0 -0 0</pose>
          <geometry>
            <box>
              <size>0.07271 0.27794 0.073</size>
            </box>
          </geometry>
          <max_contacts>10</max_contacts>
          <surface>
            <contact>
              <ode/>
            </contact>
            <bounce/>
            <friction>
              <torsional>
                <ode/>
              </torsional>
              <ode/>
            </friction>
          </surface>
        </collision>
        <collision name='base_footprint_fixed_joint_lump__lidar_mount_collision_4'>
          <pose>0.07 0 0.3412 0 -0 0</pose>
          <geometry>
            <box>
              <size>0.06 0.06 0.02</size>
            </box>
          </geometry>
          <surface>
            <contact>
              <ode/>
            </contact>
            <friction>
              <ode/>
              <torsional>
                <ode/>
              </torsional>
            </friction>
            <bounce/>
          </surface>
          <max_contacts>10</max_contacts>
        </collision>
        <collision name='base_footprint_fixed_joint_lump__lidar_link_collision_5'>
          <pose>0.07 0 0.3625 0 -0 0</pose>
          <geometry>
            <cylinder>
              <length>0.041</length>
              <radius>0.0375</radius>
            </cylinder>
          </geometry>
          <surface>
            <contact>
              <ode/>
            </contact>
            <friction>
              <ode/>
              <torsional>
                <ode/>
              </torsional>
            </friction>
            <bounce/>
          </surface>
          <max_contacts>10</max_contacts>
        </collision>
        <visual name='base_footprint_fixed_joint_lump__base_link_visual'>
          <pose>0 0 0.271 0 -0 3.14159</pose>
          <geometry>
            <box>
              <size>0.228 0.178 0.102</size>
            </box>
          </geometry>
          <material>
            <script>
              <name>Gazebo/White</name>
              <uri>file://media/materials/scripts/gazebo.material</uri>
            </script>
          </material>
        </visual>
        <visual name='base_footprint_fixed_joint_lump__camera_link_visual_1'>
          <pose>0.114 0 0.27 0 -0 3.14159</pose>
          <geometry>
            <box>
              <size>0.02 0.03 0.03</size>
            </box>
          </geometry>
          <material>
            <script>
              <name>Gazebo/Gray</name>
              <uri>file://media/materials/scripts/gazebo.material</uri>
            </script>
          </material>
        </visual>
        <visual name='base_footprint_fixed_joint_lump__depth_camera_mount_visual_2'>
          <pose>0 0 0.447 0 -0 0</pose>
          <geometry>
            <cylinder>
              <length>0.25</length>
              <radius>0.02</radius>
            </cylinder>
          </geometry>
        </visual>
        <visual name='base_footprint_fixed_joint_lump__depth_camera_link_visual_3'>
          <pose>-0.001 0 0.606 0 -0 1.5708</pose>
          <geometry>
            <mesh>
              <scale>1 1 1</scale>
              <uri>/home/joelj7258/NavRover/src/navrover_simulation/meshes/sensors/kinect.dae</uri>
            </mesh>
          </geometry>
        </visual>
        <visual name='base_footprint_fixed_joint_lump__lidar_mount_visual_4'>
          <pose>0.07 0 0.332 0 -0 0</pose>
          <geometry>
            <box>
              <size>0.06 0.06 0.02</size>
            </box>
          </geometry>
          <material>
            <script>
              <name>Gazebo/Gray</name>
              <uri>file://media/materials/scripts/gazebo.material</uri>
            </script>
          </material>
        </visual>
        <visual name='base_footprint_fixed_joint_lump__lidar_link_visual_5'>
          <pose>0.07 0 0.3625 0 -0 0</pose>
          <geometry>
            <cylinder>
              <length>0.041</length>
              <radius>0.0375</radius>
            </cylinder>
          </geometry>
          <material>
            <script>
              <name>Gazebo/Black</name>
              <uri>file://media/materials/scripts/gazebo.material</uri>
            </script>
          </material>
        </visual>
        <sensor name='camera_sensor' type='camera'>
          <update_rate>30</update_rate>
          <camera name='head'>
            <horizontal_fov>1.39626</horizontal_fov>
            <image>
              <width>640</width>
              <height>480</height>
              <format>R8G8B8</format>
            </image>
            <clip>
              <near>0.02</near>
              <far>300</far>
            </clip>
            <noise>
              <type>gaussian</type>
              <mean>0</mean>
              <stddev>0.007</stddev>
            </noise>
          </camera>
          <plugin name='camera_controller' filename='libgazebo_ros_camera.so'>
            <alwaysOn>1</alwaysOn>
            <updateRate>0.0</updateRate>
            <cameraName>rover/camera</cameraName>
            <imageTopicName>image_raw</imageTopicName>
            <cameraInfoTopicName>camera_info</cameraInfoTopicName>
            <frameName>camera_link</frameName>
            <hackBaseline>0.07</hackBaseline>
            <distortionK1>0.0</distortionK1>
            <distortionK2>0.0</distortionK2>
            <distortionK3>0.0</distortionK3>
            <distortionT1>0.0</distortionT1>
            <distortionT2>0.0</distortionT2>
            <robotNamespace>/</robotNamespace>
          </plugin>
          <pose>0.114 0 0.27 0 -0 0</pose>
        </sensor>
        <sensor name='kinect_camera' type='depth'>
          <update_rate>20</update_rate>
          <camera>
            <horizontal_fov>1.0472</horizontal_fov>
            <image>
              <width>640</width>
              <height>480</height>
              <format>R8G8B8</format>
            </image>
            <clip>
              <near>0.05</near>
              <far>3</far>
            </clip>
          </camera>
          <plugin name='kinect_camera_controller' filename='libgazebo_ros_openni_kinect.so'>
            <baseline>0.2</baseline>
            <alwaysOn>1</alwaysOn>
            <updateRate>20.0</updateRate>
            <cameraName>kinect</cameraName>
            <imageTopicName>rgb/image_raw</imageTopicName>
            <cameraInfoTopicName>rgb/camera_info</cameraInfoTopicName>
            <depthImageTopicName>depth/image_raw</depthImageTopicName>
            <depthImageCameraInfoTopicName>depth/camera_info</depthImageCameraInfoTopicName>
            <pointCloudTopicName>depth/points</pointCloudTopicName>
            <frameName>camera_depth_optical_frame</frameName>
            <pointCloudCutoff>0.5</pointCloudCutoff>
            <pointCloudCutoffMax>3.0</pointCloudCutoffMax>
            <distortionK1>0.00000001</distortionK1>
            <distortionK2>0.00000001</distortionK2>
            <distortionK3>0.00000001</distortionK3>
            <distortionT1>0.00000001</distortionT1>
            <distortionT2>0.00000001</distortionT2>
            <robotNamespace>/</robotNamespace>
          </plugin>
          <pose>0.114 0 0.27 0 -0 0</pose>
        </sensor>
        <sensor name='lidar_sensor' type='ray'>
          <visualize>0</visualize>
          <update_rate>10</update_rate>
          <ray>
            <scan>
              <horizontal>
                <samples>360</samples>
                <resolution>1</resolution>
                <min_angle>-5.6</min_angle>
                <max_angle>-0.63</max_angle>
              </horizontal>
              <vertical>
                <samples>1</samples>
                <min_angle>0</min_angle>
                <max_angle>0</max_angle>
              </vertical>
            </scan>
            <range>
              <min>0.15</min>
              <max>12</max>
              <resolution>0.01</resolution>
            </range>
            <noise>
              <type>gaussian</type>
              <mean>0</mean>
              <stddev>0.01</stddev>
            </noise>
          </ray>
          <plugin name='gazebo_ros_lidar_controller' filename='libgazebo_ros_laser.so'>
            <topicName>/scan</topicName>
            <frameName>lidar_link</frameName>
            <robotNamespace>/</robotNamespace>
          </plugin>
          <pose>0.07 0 0.342 0 -0 3.14159</pose>
        </sensor>
        <self_collide>0</self_collide>
        <enable_wind>0</enable_wind>
        <kinematic>0</kinematic>
      </link>
      <joint name='left_rocker_joint' type='revolute'>
        <pose relative_to='base_footprint'>0 -0.15 0.221 1.5708 -0 0</pose>
        <parent>base_footprint</parent>
        <child>left_rocker</child>
        <axis>
          <xyz>0 0 1</xyz>
          <limit>
            <lower>-0.24</lower>
            <upper>0.24</upper>
            <effort>100</effort>
            <velocity>100</velocity>
          </limit>
          <dynamics>
            <damping>0.1</damping>
            <friction>1</friction>
            <spring_reference>0</spring_reference>
            <spring_stiffness>0</spring_stiffness>
          </dynamics>
        </axis>
      </joint>
      <link name='left_rocker'>
        <pose relative_to='left_rocker_joint'>0 0 0 0 -0 0</pose>
        <inertial>
          <pose>0 -0.066667 0 0 -0 0</pose>
          <mass>0.9</mass>
          <inertia>
            <ixx>0.00612</ixx>
            <ixy>8.67362e-19</ixy>
            <ixz>0</ixz>
            <iyy>0.0317</iyy>
            <iyz>0</iyz>
            <izz>0.03568</izz>
          </inertia>
        </inertial>
        <collision name='left_rocker_collision'>
          <pose>0 0 0 0 -0 0</pose>
          <geometry>
            <box>
              <size>0.5 0.02 0.04</size>
            </box>
          </geometry>
          <surface>
            <contact>
              <ode/>
            </contact>
            <friction>
              <ode/>
              <torsional>
                <ode/>
              </torsional>
            </friction>
            <bounce/>
          </surface>
          <max_contacts>10</max_contacts>
        </collision>
        <collision name='left_rocker_fixed_joint_lump__motor_fl_collision_1'>
          <pose>0.23 -0.15 0 0 -0 0</pose>
          <geometry>
            <cylinder>
              <length>0.08</length>
              <radius>0.0185</radius>
            </cylinder>
          </geometry>
          <surface>
            <contact>
              <ode/>
            </contact>
            <friction>
              <ode/>
              <torsional>
                <ode/>
              </torsional>
            </friction>
            <bounce/>
          </surface>
          <max_contacts>10</max_contacts>
        </collision>
        <collision name='left_rocker_fixed_joint_lump__motor_rl_collision_2'>
          <pose>-0.23 -0.15 0 0 -0 0</pose>
          <geometry>
            <cylinder>
              <length>0.08</length>
              <radius>0.0185</radius>
            </cylinder>
          </geometry>
          <surface>
            <contact>
              <ode/>
            </contact>
            <friction>
              <ode/>
              <torsional>
                <ode/>
              </torsional>
            </friction>
            <bounce/>
          </surface>
          <max_contacts>10</max_contacts>
        </collision>
        <visual name='left_rocker_visual'>
          <pose>0 0 0 0 -0 0</pose>
          <geometry>
            <box>
              <size>0.5 0.02 0.04</size>
            </box>
          </geometry>
          <material>
            <script>
              <name>Gazebo/Gray</name>
              <uri>file://media/materials/scripts/gazebo.material</uri>
            </script>
          </material>
        </visual>
        <visual name='left_rocker_fixed_joint_lump__motor_fl_visual_1'>
          <pose>0.23 -0.15 0 0 -0 0</pose>
          <geometry>
            <cylinder>
              <length>0.08</length>
              <radius>0.0185</radius>
            </cylinder>
          </geometry>
          <material>
            <script>
              <name>Gazebo/Gray</name>
              <uri>file://media/materials/scripts/gazebo.material</uri>
            </script>
          </material>
        </visual>
        <visual name='left_rocker_fixed_joint_lump__motor_rl_visual_2'>
          <pose>-0.23 -0.15 0 0 -0 0</pose>
          <geometry>
            <cylinder>
              <length>0.08</length>
              <radius>0.0185</radius>
            </cylinder>
          </geometry>
          <material>
            <script>
              <name>Gazebo/Gray</name>
              <uri>file://media/materials/scripts/gazebo.material</uri>
            </script>
          </material>
        </visual>
        <self_collide>0</self_collide>
        <enable_wind>0</enable_wind>
        <kinematic>0</kinematic>
      </link>
      <joint name='wheel_fl_joint' type='revolute'>
        <pose relative_to='left_rocker'>0.23 -0.15 0.07 3.14159 -0 0</pose>
        <parent>left_rocker</parent>
        <child>wheel_fl</child>
        <axis>
          <xyz>0 0 1</xyz>
          <limit>
            <effort>2</effort>
            <velocity>6</velocity>
            <lower>-1e+16</lower>
            <upper>1e+16</upper>
          </limit>
          <dynamics>
            <damping>0.1</damping>
            <friction>0.3125</friction>
            <spring_reference>0</spring_reference>
            <spring_stiffness>0</spring_stiffness>
          </dynamics>
        </axis>
      </joint>
      <link name='wheel_fl'>
        <pose relative_to='wheel_fl_joint'>0 0 0 0 -0 0</pose>
        <inertial>
          <pose>0 0 0 0 -0 0</pose>
          <mass>0.5</mass>
          <inertia>
            <ixx>0.00032</ixx>
            <ixy>0</ixy>
            <ixz>0</ixz>
            <iyy>0.00032</iyy>
            <iyz>0</iyz>
            <izz>0.00063</izz>
          </inertia>
        </inertial>
        <collision name='wheel_fl_collision'>
          <pose>0 0 0 0 -0 0</pose>
          <geometry>
            <cylinder>
              <length>0.058785</length>
              <radius>0.065</radius>
            </cylinder>
          </geometry>
          <surface>
            <contact>
              <ode/>
            </contact>
            <friction>
              <ode/>
              <torsional>
                <ode/>
              </torsional>
            </friction>
            <bounce/>
          </surface>
          <max_contacts>10</max_contacts>
        </collision>
        <visual name='wheel_fl_visual'>
          <pose>0 0 0 0 -0 0</pose>
          <geometry>
            <cylinder>
              <length>0.058785</length>
              <radius>0.065</radius>
            </cylinder>
          </geometry>
          <material>
            <script>
              <name>Gazebo/Black</name>
              <uri>file://media/materials/scripts/gazebo.material</uri>
            </script>
          </material>
        </visual>
        <self_collide>0</self_collide>
        <enable_wind>0</enable_wind>
        <kinematic>0</kinematic>
      </link>
      <joint name='wheel_rl_joint' type='revolute'>
        <pose relative_to='left_rocker'>-0.23 -0.15 0.07 3.14159 -0 0</pose>
        <parent>left_rocker</parent>
        <child>wheel_rl</child>
        <axis>
          <xyz>0 0 1</xyz>
          <limit>
            <effort>2</effort>
            <velocity>6</velocity>
            <lower>-1e+16</lower>
            <upper>1e+16</upper>
          </limit>
          <dynamics>
            <damping>0.1</damping>
            <friction>0.3125</friction>
            <spring_reference>0</spring_reference>
            <spring_stiffness>0</spring_stiffness>
          </dynamics>
        </axis>
      </joint>
      <link name='wheel_rl'>
        <pose relative_to='wheel_rl_joint'>0 0 0 0 -0 0</pose>
        <inertial>
          <pose>0 0 0 0 -0 0</pose>
          <mass>0.5</mass>
          <inertia>
            <ixx>0.00032</ixx>
            <ixy>0</ixy>
            <ixz>0</ixz>
            <iyy>0.00032</iyy>
            <iyz>0</iyz>
            <izz>0.00063</izz>
          </inertia>
        </inertial>
        <collision name='wheel_rl_collision'>
          <pose>0 0 0 0 -0 0</pose>
          <geometry>
            <cylinder>
              <length>0.058785</length>
              <radius>0.065</radius>
            </cylinder>
          </geometry>
          <surface>
            <contact>
              <ode/>
            </contact>
            <friction>
              <ode/>
              <torsional>
                <ode/>
              </torsional>
            </friction>
            <bounce/>
          </surface>
          <max_contacts>10</max_contacts>
        </collision>
        <visual name='wheel_rl_visual'>
          <pose>0 0 0 0 -0 0</pose>
          <geometry>
            <cylinder>
              <length>0.058785</length>
              <radius>0.065</radius>
            </cylinder>
          </geometry>
          <material>
            <script>
              <name>Gazebo/Black</name>
              <uri>file://media/materials/scripts/gazebo.material</uri>
            </script>
          </material>
        </visual>
        <self_collide>0</self_collide>
        <enable_wind>0</enable_wind>
        <kinematic>0</kinematic>
      </link>
      <joint name='right_rocker_joint' type='revolute'>
        <pose relative_to='base_footprint'>0 0.15 0.221 1.5708 -0 0</pose>
        <parent>base_footprint</parent>
        <child>right_rocker</child>
        <axis>
          <xyz>0 0 1</xyz>
          <limit>
            <lower>-0.24</lower>
            <upper>0.24</upper>
            <effort>100</effort>
            <velocity>100</velocity>
          </limit>
          <dynamics>
            <damping>0.1</damping>
            <friction>1</friction>
            <spring_reference>0</spring_reference>
            <spring_stiffness>0</spring_stiffness>
          </dynamics>
        </axis>
      </joint>
      <link name='right_rocker'>
        <pose relative_to='right_rocker_joint'>0 0 0 0 -0 0</pose>
        <inertial>
          <pose>0 -0.066667 0 0 -0 0</pose>
          <mass>0.9</mass>
          <inertia>
            <ixx>0.00612</ixx>
            <ixy>8.67362e-19</ixy>
            <ixz>0</ixz>
            <iyy>0.0317</iyy>
            <iyz>0</iyz>
            <izz>0.03568</izz>
          </inertia>
        </inertial>
        <collision name='right_rocker_collision'>
          <pose>0 0 0 0 -0 0</pose>
          <geometry>
            <box>
              <size>0.5 0.02 0.04</size>
            </box>
          </geometry>
          <surface>
            <contact>
              <ode/>
            </contact>
            <friction>
              <ode/>
              <torsional>
                <ode/>
              </torsional>
            </friction>
            <bounce/>
          </surface>
          <max_contacts>10</max_contacts>
        </collision>
        <collision name='right_rocker_fixed_joint_lump__motor_fr_collision_1'>
          <pose>0.23 -0.15 0 0 -0 0</pose>
          <geometry>
            <cylinder>
              <length>0.08</length>
              <radius>0.0185</radius>
            </cylinder>
          </geometry>
          <surface>
            <contact>
              <ode/>
            </contact>
            <friction>
              <ode/>
              <torsional>
                <ode/>
              </torsional>
            </friction>
            <bounce/>
          </surface>
          <max_contacts>10</max_contacts>
        </collision>
        <collision name='right_rocker_fixed_joint_lump__motor_rr_collision_2'>
          <pose>-0.23 -0.15 0 0 -0 0</pose>
          <geometry>
            <cylinder>
              <length>0.08</length>
              <radius>0.0185</radius>
            </cylinder>
          </geometry>
          <surface>
            <contact>
              <ode/>
            </contact>
            <friction>
              <ode/>
              <torsional>
                <ode/>
              </torsional>
            </friction>
            <bounce/>
          </surface>
          <max_contacts>10</max_contacts>
        </collision>
        <visual name='right_rocker_visual'>
          <pose>0 0 0 0 -0 0</pose>
          <geometry>
            <box>
              <size>0.5 0.02 0.04</size>
            </box>
          </geometry>
          <material>
            <script>
              <name>Gazebo/Gray</name>
              <uri>file://media/materials/scripts/gazebo.material</uri>
            </script>
          </material>
        </visual>
        <visual name='right_rocker_fixed_joint_lump__motor_fr_visual_1'>
          <pose>0.23 -0.15 0 0 -0 0</pose>
          <geometry>
            <cylinder>
              <length>0.08</length>
              <radius>0.0185</radius>
            </cylinder>
          </geometry>
          <material>
            <script>
              <name>Gazebo/Gray</name>
              <uri>file://media/materials/scripts/gazebo.material</uri>
            </script>
          </material>
        </visual>
        <visual name='right_rocker_fixed_joint_lump__motor_rr_visual_2'>
          <pose>-0.23 -0.15 0 0 -0 0</pose>
          <geometry>
            <cylinder>
              <length>0.08</length>
              <radius>0.0185</radius>
            </cylinder>
          </geometry>
          <material>
            <script>
              <name>Gazebo/Gray</name>
              <uri>file://media/materials/scripts/gazebo.material</uri>
            </script>
          </material>
        </visual>
        <self_collide>0</self_collide>
        <enable_wind>0</enable_wind>
        <kinematic>0</kinematic>
      </link>
      <joint name='wheel_fr_joint' type='revolute'>
        <pose relative_to='right_rocker'>0.23 -0.15 -0.07 3.14159 -0 0</pose>
        <parent>right_rocker</parent>
        <child>wheel_fr</child>
        <axis>
          <xyz>0 0 1</xyz>
          <limit>
            <effort>2</effort>
            <velocity>6</velocity>
            <lower>-1e+16</lower>
            <upper>1e+16</upper>
          </limit>
          <dynamics>
            <damping>0.1</damping>
            <friction>0.3125</friction>
            <spring_reference>0</spring_reference>
            <spring_stiffness>0</spring_stiffness>
          </dynamics>
        </axis>
      </joint>
      <link name='wheel_fr'>
        <pose relative_to='wheel_fr_joint'>0 0 0 0 -0 0</pose>
        <inertial>
          <pose>0 0 0 0 -0 0</pose>
          <mass>0.5</mass>
          <inertia>
            <ixx>0.00032</ixx>
            <ixy>0</ixy>
            <ixz>0</ixz>
            <iyy>0.00032</iyy>
            <iyz>0</iyz>
            <izz>0.00063</izz>
          </inertia>
        </inertial>
        <collision name='wheel_fr_collision'>
          <pose>0 0 0 0 -0 0</pose>
          <geometry>
            <cylinder>
              <length>0.058785</length>
              <radius>0.065</radius>
            </cylinder>
          </geometry>
          <surface>
            <contact>
              <ode/>
            </contact>
            <friction>
              <ode/>
              <torsional>
                <ode/>
              </torsional>
            </friction>
            <bounce/>
          </surface>
          <max_contacts>10</max_contacts>
        </collision>
        <visual name='wheel_fr_visual'>
          <pose>0 0 0 0 -0 0</pose>
          <geometry>
            <cylinder>
              <length>0.058785</length>
              <radius>0.065</radius>
            </cylinder>
          </geometry>
          <material>
            <script>
              <name>Gazebo/Black</name>
              <uri>file://media/materials/scripts/gazebo.material</uri>
            </script>
          </material>
        </visual>
        <self_collide>0</self_collide>
        <enable_wind>0</enable_wind>
        <kinematic>0</kinematic>
      </link>
      <joint name='wheel_rr_joint' type='revolute'>
        <pose relative_to='right_rocker'>-0.23 -0.15 -0.07 3.14159 -0 0</pose>
        <parent>right_rocker</parent>
        <child>wheel_rr</child>
        <axis>
          <xyz>0 0 1</xyz>
          <limit>
            <effort>2</effort>
            <velocity>6</velocity>
            <lower>-1e+16</lower>
            <upper>1e+16</upper>
          </limit>
          <dynamics>
            <damping>0.1</damping>
            <friction>0.3125</friction>
            <spring_reference>0</spring_reference>
            <spring_stiffness>0</spring_stiffness>
          </dynamics>
        </axis>
      </joint>
      <link name='wheel_rr'>
        <pose relative_to='wheel_rr_joint'>0 0 0 0 -0 0</pose>
        <inertial>
          <pose>0 0 0 0 -0 0</pose>
          <mass>0.5</mass>
          <inertia>
            <ixx>0.00032</ixx>
            <ixy>0</ixy>
            <ixz>0</ixz>
            <iyy>0.00032</iyy>
            <iyz>0</iyz>
            <izz>0.00063</izz>
          </inertia>
        </inertial>
        <collision name='wheel_rr_collision'>
          <pose>0 0 0 0 -0 0</pose>
          <geometry>
            <cylinder>
              <length>0.058785</length>
              <radius>0.065</radius>
            </cylinder>
          </geometry>
          <surface>
            <contact>
              <ode/>
            </contact>
            <friction>
              <ode/>
              <torsional>
                <ode/>
              </torsional>
            </friction>
            <bounce/>
          </surface>
          <max_contacts>10</max_contacts>
        </collision>
        <visual name='wheel_rr_visual'>
          <pose>0 0 0 0 -0 0</pose>
          <geometry>
            <cylinder>
              <length>0.058785</length>
              <radius>0.065</radius>
            </cylinder>
          </geometry>
          <material>
            <script>
              <name>Gazebo/Black</name>
              <uri>file://media/materials/scripts/gazebo.material</uri>
            </script>
          </material>
        </visual>
        <self_collide>0</self_collide>
        <enable_wind>0</enable_wind>
        <kinematic>0</kinematic>
      </link>
      <plugin name='rocker_differential' filename='libleo_gazebo_differential_plugin.so'>
        <jointA>left_rocker_joint</jointA>
        <jointB>right_rocker_joint</jointB>
        <forceConstant>75.0</forceConstant>
        <robotNamespace>/</robotNamespace>
      </plugin>
      <plugin name='gazebo_ros_control' filename='libgazebo_ros_control.so'>
        <robotNamespace>/rover</robotNamespace>
        <robotSimType>gazebo_ros_control/DefaultRobotHWSim</robotSimType>
        <legacyModeNS>1</legacyModeNS>
      </plugin>
      <plugin name='joint_state_publisher' filename='libgazebo_ros_joint_state_publisher.so'>
        <robotNamespace>/rover</robotNamespace>
        <jointName>left_rocker_joint, right_rocker_joint, wheel_fl_joint, wheel_fr_joint, wheel_rl_joint, wheel_rr_joint</jointName>
        <updateRate>50.0</updateRate>
        <alwaysOn>1</alwaysOn>
      </plugin>
      <static>0</static>
      <plugin name='skid_steer_drive_controller' filename='libgazebo_ros_skid_steer_drive.so'>
        <updateRate>100.0</updateRate>
        <leftFrontJoint>wheel_fl_joint</leftFrontJoint>
        <rightFrontJoint>wheel_fr_joint</rightFrontJoint>
        <leftRearJoint>wheel_rl_joint</leftRearJoint>
        <rightRearJoint>wheel_rr_joint</rightRearJoint>
        <wheelSeparation>0.419308</wheelSeparation>
        <wheelDiameter>0.13</wheelDiameter>
        <robotBaseFrame>base_footprint</robotBaseFrame>
        <torque>15</torque>
        <topicName>/cmd_vel</topicName>
        <broadcastTF>1</broadcastTF>
        <publishWheelJointState>1</publishWheelJointState>
        <robotNamespace>/</robotNamespace>
      </plugin>
      <pose>0 0 0.22 0 -0 0</pose>
    </model>
    <model name='test_zone'>
      <link name='link'>
        <inertial>
          <mass>15</mass>
          <inertia>
            <ixx>0</ixx>
            <ixy>0</ixy>
            <ixz>0</ixz>
            <iyy>0</iyy>
            <iyz>0</iyz>
            <izz>0.1</izz>
          </inertia>
        </inertial>
        <collision name='collision'>
          <pose>-8.12 8.8 0 1.57 -0 0</pose>
          <geometry>
            <mesh>
              <uri>model://test_zone/meshes/building.dae</uri>
            </mesh>
          </geometry>
          <max_contacts>10</max_contacts>
          <surface>
            <contact>
              <ode/>
            </contact>
            <bounce/>
            <friction>
              <torsional>
                <ode/>
              </torsional>
              <ode/>
            </friction>
          </surface>
        </collision>
        <visual name='visual'>
          <pose>-8.12 8.8 0 1.57 -0 0</pose>
          <geometry>
            <mesh>
              <uri>model://test_zone/meshes/building.dae</uri>
            </mesh>
          </geometry>
        </visual>
        <self_collide>0</self_collide>
        <enable_wind>0</enable_wind>
        <kinematic>0</kinematic>
      </link>
      <static>1</static>
      <pose>-1.124 -0.307776 0 0 -0 0</pose>
    </model>
    <model name='debris_3_2'>
      <link name='link_6'>
        <pose>0 0 0 0 -0 0</pose>
        <inertial>
          <mass>1</mass>
          <inertia>
            <ixx>0.166667</ixx>
            <ixy>0</ixy>
            <ixz>0</ixz>
            <iyy>0.166667</iyy>
            <iyz>0</iyz>
            <izz>0.166667</izz>
          </inertia>
        </inertial>
        <visual name='visual'>
          <pose>0 0 0 0 -0 0</pose>
          <geometry>
            <mesh>
              <uri>model://debris_3_2/meshes/debris_3_2.dae</uri>
              <scale>1 1 1</scale>
            </mesh>
          </geometry>
          <material>
            <script>
              <uri>model://debris_3_2/materials/scripts</uri>
              <uri>model://debris_3_2/materials/textures</uri>
              <name>debris_3</name>
            </script>
          </material>
          <cast_shadows>1</cast_shadows>
          <transparency>0</transparency>
        </visual>
        <collision name='collision'>
          <laser_retro>0</laser_retro>
          <max_contacts>10</max_contacts>
          <pose>0 0 0 0 -0 0</pose>
          <geometry>
            <mesh>
              <uri>model://debris_3_2/meshes/debris_3_2.dae</uri>
              <scale>1 1 1</scale>
            </mesh>
          </geometry>
          <surface>
            <contact>
              <ode/>
            </contact>
            <bounce/>
            <friction>
              <torsional>
                <ode/>
              </torsional>
              <ode/>
            </friction>
          </surface>
        </collision>
        <self_collide>0</self_collide>
        <enable_wind>0</enable_wind>
        <kinematic>0</kinematic>
      </link>
      <static>1</static>
      <allow_auto_disable>1</allow_auto_disable>
      <pose>3.21106 5.87887 0 0 -0 0</pose>
    </model>
    <model name='debris_3_1'>
      <link name='link_5'>
        <pose>0 0 0 0 -0 0</pose>
        <inertial>
          <mass>1</mass>
          <inertia>
            <ixx>0.166667</ixx>
            <ixy>0</ixy>
            <ixz>0</ixz>
            <iyy>0.166667</iyy>
            <iyz>0</iyz>
            <izz>0.166667</izz>
          </inertia>
        </inertial>
        <visual name='visual'>
          <pose>0 0 0 0 -0 0</pose>
          <geometry>
            <mesh>
              <uri>model://debris_3_1/meshes/debris_3_1.dae</uri>
              <scale>1 1 1</scale>
            </mesh>
          </geometry>
          <material>
            <script>
              <uri>model://debris_3_1/materials/scripts</uri>
              <uri>model://debris_3_1/materials/textures</uri>
              <name>debris_3</name>
            </script>
          </material>
          <cast_shadows>1</cast_shadows>
          <transparency>0</transparency>
        </visual>
        <collision name='collision'>
          <laser_retro>0</laser_retro>
          <max_contacts>10</max_contacts>
          <pose>0 0 0 0 -0 0</pose>
          <geometry>
            <mesh>
              <uri>model://debris_3_1/meshes/debris_3_1.dae</uri>
              <scale>1 1 1</scale>
            </mesh>
          </geometry>
          <surface>
            <contact>
              <ode/>
            </contact>
            <bounce/>
            <friction>
              <torsional>
                <ode/>
              </torsional>
              <ode/>
            </friction>
          </surface>
        </collision>
        <self_collide>0</self_collide>
        <enable_wind>0</enable_wind>
        <kinematic>0</kinematic>
      </link>
      <static>1</static>
      <allow_auto_disable>1</allow_auto_disable>
      <pose>2.88787 4.11191 0 0 -0 0</pose>
    </model>
    <model name='debris_3_1_0'>
      <link name='link_5'>
        <pose>0 0 0 0 -0 0</pose>
        <inertial>
          <mass>1</mass>
          <inertia>
            <ixx>0.166667</ixx>
            <ixy>0</ixy>
            <ixz>0</ixz>
            <iyy>0.166667</iyy>
            <iyz>0</iyz>
            <izz>0.166667</izz>
          </inertia>
        </inertial>
        <visual name='visual'>
          <pose>0 0 0 0 -0 0</pose>
          <geometry>
            <mesh>
              <uri>model://debris_3_1/meshes/debris_3_1.dae</uri>
              <scale>1 1 1</scale>
            </mesh>
          </geometry>
          <material>
            <script>
              <uri>model://debris_3_1/materials/scripts</uri>
              <uri>model://debris_3_1/materials/textures</uri>
              <name>debris_3</name>
            </script>
          </material>
          <cast_shadows>1</cast_shadows>
          <transparency>0</transparency>
        </visual>
        <collision name='collision'>
          <laser_retro>0</laser_retro>
          <max_contacts>10</max_contacts>
          <pose>0 0 0 0 -0 0</pose>
          <geometry>
            <mesh>
              <uri>model://debris_3_1/meshes/debris_3_1.dae</uri>
              <scale>1 1 1</scale>
            </mesh>
          </geometry>
          <surface>
            <contact>
              <ode/>
            </contact>
            <bounce/>
            <friction>
              <torsional>
                <ode/>
              </torsional>
              <ode/>
            </friction>
          </surface>
        </collision>
        <self_collide>0</self_collide>
        <enable_wind>0</enable_wind>
        <kinematic>0</kinematic>
      </link>
      <static>1</static>
      <allow_auto_disable>1</allow_auto_disable>
      <pose>3.79905 4.12234 0 0 -0 0</pose>
    </model>
    <model name='debris_3_1_1'>
      <link name='link_5'>
        <pose>0 0 0 0 -0 0</pose>
        <inertial>
          <mass>1</mass>
          <inertia>
            <ixx>0.166667</ixx>
            <ixy>0</ixy>
            <ixz>0</ixz>
            <iyy>0.166667</iyy>
            <iyz>0</iyz>
            <izz>0.166667</izz>
          </inertia>
        </inertial>
        <visual name='visual'>
          <pose>0 0 0 0 -0 0</pose>
          <geometry>
            <mesh>
              <uri>model://debris_3_1/meshes/debris_3_1.dae</uri>
              <scale>1 1 1</scale>
            </mesh>
          </geometry>
          <material>
            <script>
              <uri>model://debris_3_1/materials/scripts</uri>
              <uri>model://debris_3_1/materials/textures</uri>
              <name>debris_3</name>
            </script>
          </material>
          <cast_shadows>1</cast_shadows>
          <transparency>0</transparency>
        </visual>
        <collision name='collision'>
          <laser_retro>0</laser_retro>
          <max_contacts>10</max_contacts>
          <pose>0 0 0 0 -0 0</pose>
          <geometry>
            <mesh>
              <uri>model://debris_3_1/meshes/debris_3_1.dae</uri>
              <scale>1 1 1</scale>
            </mesh>
          </geometry>
          <surface>
            <contact>
              <ode/>
            </contact>
            <bounce/>
            <friction>
              <torsional>
                <ode/>
              </torsional>
              <ode/>
            </friction>
          </surface>
        </collision>
        <self_collide>0</self_collide>
        <enable_wind>0</enable_wind>
        <kinematic>0</kinematic>
      </link>
      <static>1</static>
      <allow_auto_disable>1</allow_auto_disable>
      <pose>3.04775 2.54522 0 0 -0 0</pose>
    </model>
    <model name='debris_3_1_2'>
      <link name='link_5'>
        <pose>0 0 0 0 -0 0</pose>
        <inertial>
          <mass>1</mass>
          <inertia>
            <ixx>0.166667</ixx>
            <ixy>0</ixy>
            <ixz>0</ixz>
            <iyy>0.166667</iyy>
            <iyz>0</iyz>
            <izz>0.166667</izz>
          </inertia>
        </inertial>
        <visual name='visual'>
          <pose>0 0 0 0 -0 0</pose>
          <geometry>
            <mesh>
              <uri>model://debris_3_1/meshes/debris_3_1.dae</uri>
              <scale>1 1 1</scale>
            </mesh>
          </geometry>
          <material>
            <script>
              <uri>model://debris_3_1/materials/scripts</uri>
              <uri>model://debris_3_1/materials/textures</uri>
              <name>debris_3</name>
            </script>
          </material>
          <cast_shadows>1</cast_shadows>
          <transparency>0</transparency>
        </visual>
        <collision name='collision'>
          <laser_retro>0</laser_retro>
          <max_contacts>10</max_contacts>
          <pose>0 0 0 0 -0 0</pose>
          <geometry>
            <mesh>
              <uri>model://debris_3_1/meshes/debris_3_1.dae</uri>
              <scale>1 1 1</scale>
            </mesh>
          </geometry>
          <surface>
            <contact>
              <ode/>
            </contact>
            <bounce/>
            <friction>
              <torsional>
                <ode/>
              </torsional>
              <ode/>
            </friction>
          </surface>
        </collision>
        <self_collide>0</self_collide>
        <enable_wind>0</enable_wind>
        <kinematic>0</kinematic>
      </link>
      <static>1</static>
      <allow_auto_disable>1</allow_auto_disable>
      <pose>3.93208 2.53705 0 0 -0 0</pose>
    </model>
    <state world_name='default'>
      <sim_time>134 184000000</sim_time>
      <real_time>140 568306925</real_time>
      <wall_time>1721223002 845395989</wall_time>
      <iterations>134184</iterations>
      <model name='debris_3_1'>
        <pose>2.88787 4.11191 0 0 -0 0</pose>
        <scale>1 1 1</scale>
        <link name='link_5'>
          <pose>2.88787 4.11191 0 0 -0 0</pose>
          <velocity>0 0 0 0 -0 0</velocity>
          <acceleration>0 0 0 0 -0 0</acceleration>
          <wrench>0 0 0 0 -0 0</wrench>
        </link>
      </model>
      <model name='debris_3_1_0'>
        <pose>3.79905 4.12234 0 0 -0 0</pose>
        <scale>1 1 1</scale>
        <link name='link_5'>
          <pose>3.79905 4.12234 0 0 -0 0</pose>
          <velocity>0 0 0 0 -0 0</velocity>
          <acceleration>0 0 0 0 -0 0</acceleration>
          <wrench>0 0 0 0 -0 0</wrench>
        </link>
      </model>
      <model name='debris_3_1_1'>
        <pose>2.92671 2.54522 0 0 -0 0</pose>
        <scale>1 1 1</scale>
        <link name='link_5'>
          <pose>2.92671 2.54522 0 0 -0 0</pose>
          <velocity>0 0 0 0 -0 0</velocity>
          <acceleration>0 0 0 0 -0 0</acceleration>
          <wrench>0 0 0 0 -0 0</wrench>
        </link>
      </model>
      <model name='debris_3_1_2'>
        <pose>3.83415 2.49558 0 0 -0 0</pose>
        <scale>1 1 1</scale>
        <link name='link_5'>
          <pose>3.83415 2.49558 0 0 -0 0</pose>
          <velocity>0 0 0 0 -0 0</velocity>
          <acceleration>0 0 0 0 -0 0</acceleration>
          <wrench>0 0 0 0 -0 0</wrench>
        </link>
      </model>
      <model name='debris_3_2'>
        <pose>3.21106 5.87887 0 0 -0 0</pose>
        <scale>1 1 1</scale>
        <link name='link_6'>
          <pose>3.21106 5.87887 0 0 -0 0</pose>
          <velocity>0 0 0 0 -0 0</velocity>
          <acceleration>0 0 0 0 -0 0</acceleration>
          <wrench>0 0 0 0 -0 0</wrench>
        </link>
      </model>
      <model name='ground_plane'>
        <pose>0 0 0 0 -0 0</pose>
        <scale>1 1 1</scale>
        <link name='link'>
          <pose>0 0 0 0 -0 0</pose>
          <velocity>0 0 0 0 -0 0</velocity>
          <acceleration>0 0 0 0 -0 0</acceleration>
          <wrench>0 0 0 0 -0 0</wrench>
        </link>
      </model>
      <model name='rover'>
        <pose>0.01061 4e-06 -0.006003 1.7e-05 -0.002545 -0.000359</pose>
        <scale>1 1 1</scale>
        <link name='base_footprint'>
          <pose>0.01061 4e-06 -0.006003 1.7e-05 -0.002545 -0.000359</pose>
          <velocity>0.00031 0.003159 -0.004234 0.019926 -0.000105 0.001308</velocity>
          <acceleration>-0.152222 -1.44647 -8.47141 1.30615 -0.582754 1.64036</acceleration>
          <wrench>-0.828849 -7.87603 -46.1268 0 -0 0</wrench>
        </link>
        <link name='left_rocker'>
          <pose>0.009994 -0.149999 0.214994 1.57082 -0 -0.000359</pose>
          <velocity>0.000365 -0.001348 -0.007258 0.019826 -0.000106 0.001247</velocity>
          <acceleration>0.087954 -0.543052 -9.34067 1.17623 -0.592436 1.75249</acceleration>
          <wrench>0.079159 -0.488747 -8.4066 0 -0 0</wrench>
        </link>
        <link name='right_rocker'>
          <pose>0.010101 0.15 0.214999 1.57082 -0 -0.000358</pose>
          <velocity>8.2e-05 -0.001356 -0.001147 0.019911 -0.000104 0.000653</velocity>
          <acceleration>-0.291248 -0.667476 -7.47507 0.487964 -0.878347 1.20003</acceleration>
          <wrench>-0.262123 -0.600729 -6.72756 0 -0 0</wrench>
        </link>
        <link name='wheel_fl'>
          <pose>0.239968 -0.220078 0.064993 -1.57075 0.164195 -0.000342</pose>
          <velocity>0.000547 0.001806 -0.008655 0.01216 -0.000104 -0.000879</velocity>
          <acceleration>0.235012 0.635644 -9.67291 -1.55583 -1.44612 2.0844</acceleration>
          <wrench>0.117506 0.317822 -4.83646 0 -0 0</wrench>
        </link>
        <link name='wheel_fr'>
          <pose>0.240126 0.219919 0.065 -1.57086 0.154377 -0.000365</pose>
          <velocity>5.4e-05 0.001263 0.000286 -0.018628 0.000527 0.000654</velocity>
          <acceleration>-0.177736 0.251212 -6.86252 0.068304 -1.38433 -1.73089</acceleration>
          <wrench>-0.088868 0.125606 -3.43126 0 -0 0</wrench>
        </link>
        <link name='wheel_rl'>
          <pose>-0.220031 -0.219913 0.064993 -1.57074 0.12951 -0.000345</pose>
          <velocity>0.000384 0.001175 -0.008688 0.010441 -0.000161 -0.000445</velocity>
          <acceleration>0.272347 -0.02361 -9.85816 -2.84966 -0.410668 -2.37989</acceleration>
          <wrench>0.136174 -0.011805 -4.92908 0 -0 0</wrench>
        </link>
        <link name='wheel_rr'>
          <pose>-0.219874 0.220084 0.065 -1.57085 0.137905 -0.000356</pose>
          <velocity>4e-05 0.001032 0.000302 -0.015124 0.000888 -0.000642</velocity>
          <acceleration>-0.233706 -0.176986 -7.35309 0.331996 -1.19942 2.31425</acceleration>
          <wrench>-0.116853 -0.088493 -3.67655 0 -0 0</wrench>
        </link>
      </model>
      <model name='test_zone'>
        <pose>-1.124 -0.307776 0 0 -0 0</pose>
        <scale>1 1 1</scale>
        <link name='link'>
          <pose>-1.124 -0.307776 0 0 -0 0</pose>
          <velocity>0 0 0 0 -0 0</velocity>
          <acceleration>0 0 0 0 -0 0</acceleration>
          <wrench>0 0 0 0 -0 0</wrench>
        </link>
      </model>
      <light name='sun'>
        <pose>0 0 10 0 -0 0</pose>
      </light>
    </state>
    <gui fullscreen='0'>
      <camera name='user_camera'>
        <pose>-0.512245 -0.998044 23.0102 1.4e-05 1.5698 1.62419</pose>
        <view_controller>orbit</view_controller>
        <projection_type>perspective</projection_type>
      </camera>
    </gui>
  </world>
</sdf>
