<?xml version="1.0" ?>
<robot name="navrover" xmlns:xacro="http://www.ros.org/wiki/xacro">

<xacro:include filename="$(find navrover_description)/urdf/materials.xacro" />
<xacro:include filename="$(find navrover_description)/urdf/navrover.trans" />
<xacro:include filename="$(find navrover_description)/urdf/navrover.gazebo" />
<link name="base_link">
  <inertial>
    <origin xyz="0.009504858866791937 -0.002270281447422617 0.1951992873261795" rpy="0 0 0"/>
    <mass value="0.9518707421963939"/>
    <inertia ixx="0.005453" iyy="0.006479" izz="0.009221" ixy="8e-06" iyz="-2.3e-05" ixz="1.9e-05"/>
  </inertial>
  <visual>
    <origin xyz="0 0 0" rpy="0 0 0"/>
    <geometry>
      <mesh filename="file://$(find navrover_description)/meshes/base_link.stl" scale="0.001 0.001 0.001"/>
    </geometry>
    <material name="silver"/>
  </visual>
  <collision>
    <origin xyz="0 0 0" rpy="0 0 0"/>
    <geometry>
      <mesh filename="file://$(find navrover_description)/meshes/base_link.stl" scale="0.001 0.001 0.001"/>
    </geometry>
  </collision>
</link>

<link name="left_front_motor_1">
  <inertial>
    <origin xyz="0.0008910668948025613 -0.03289510779057839 -0.06734484283672734" rpy="0 0 0"/>
    <mass value="0.8027582890758764"/>
    <inertia ixx="0.000756" iyy="0.000377" izz="0.000565" ixy="1.3e-05" iyz="-4.8e-05" ixz="6.6e-05"/>
  </inertial>
  <visual>
    <origin xyz="-0.259316 -0.15026 -0.142476" rpy="0 0 0"/>
    <geometry>
      <mesh filename="file://$(find navrover_description)/meshes/left_front_motor_1.stl" scale="0.001 0.001 0.001"/>
    </geometry>
    <material name="silver"/>
  </visual>
  <collision>
    <origin xyz="-0.259316 -0.15026 -0.142476" rpy="0 0 0"/>
    <geometry>
      <mesh filename="file://$(find navrover_description)/meshes/left_front_motor_1.stl" scale="0.001 0.001 0.001"/>
    </geometry>
  </collision>
</link>

<link name="right_rear_motor_1">
  <inertial>
    <origin xyz="-0.000890443487994802 0.032894483907466535 -0.06734484283672845" rpy="0 0 0"/>
    <mass value="0.8027582890758764"/>
    <inertia ixx="0.000756" iyy="0.000377" izz="0.000565" ixy="1.3e-05" iyz="4.8e-05" ixz="-6.6e-05"/>
  </inertial>
  <visual>
    <origin xyz="0.240684 0.156507 -0.142476" rpy="0 0 0"/>
    <geometry>
      <mesh filename="file://$(find navrover_description)/meshes/right_rear_motor_1.stl" scale="0.001 0.001 0.001"/>
    </geometry>
    <material name="silver"/>
  </visual>
  <collision>
    <origin xyz="0.240684 0.156507 -0.142476" rpy="0 0 0"/>
    <geometry>
      <mesh filename="file://$(find navrover_description)/meshes/right_rear_motor_1.stl" scale="0.001 0.001 0.001"/>
    </geometry>
  </collision>
</link>

<link name="right_front_motor_1">
  <inertial>
    <origin xyz="0.0007239698752933288 0.032862866662436055 -0.06750730161649608" rpy="0 0 0"/>
    <mass value="0.8025906335235503"/>
    <inertia ixx="0.000756" iyy="0.000377" izz="0.000564" ixy="-1.3e-05" iyz="4.8e-05" ixz="6.5e-05"/>
  </inertial>
  <visual>
    <origin xyz="-0.259316 0.156507 -0.142476" rpy="0 0 0"/>
    <geometry>
      <mesh filename="file://$(find navrover_description)/meshes/right_front_motor_1.stl" scale="0.001 0.001 0.001"/>
    </geometry>
    <material name="silver"/>
  </visual>
  <collision>
    <origin xyz="-0.259316 0.156507 -0.142476" rpy="0 0 0"/>
    <geometry>
      <mesh filename="file://$(find navrover_description)/meshes/right_front_motor_1.stl" scale="0.001 0.001 0.001"/>
    </geometry>
  </collision>
</link>

<link name="right_rocker_arm_1">
  <inertial>
    <origin xyz="2.9281474290231146e-07 0.02209292999064974 -0.0201262955007033" rpy="0 0 0"/>
    <mass value="0.4257120617987387"/>
    <inertia ixx="8.7e-05" iyy="0.008739" izz="0.008786" ixy="-0.0" iyz="-1e-06" ixz="-0.0"/>
  </inertial>
  <visual>
    <origin xyz="-0.009316 0.178074 -0.172741" rpy="0 0 0"/>
    <geometry>
      <mesh filename="file://$(find navrover_description)/meshes/right_rocker_arm_1.stl" scale="0.001 0.001 0.001"/>
    </geometry>
    <material name="silver"/>
  </visual>
  <collision>
    <origin xyz="-0.009316 0.178074 -0.172741" rpy="0 0 0"/>
    <geometry>
      <mesh filename="file://$(find navrover_description)/meshes/right_rocker_arm_1.stl" scale="0.001 0.001 0.001"/>
    </geometry>
  </collision>
</link>

<link name="left_rocker_arm_1">
  <inertial>
    <origin xyz="3.324283158120944e-07 0.01853003784791249 -0.02012629550070319" rpy="0 0 0"/>
    <mass value="0.4257120617987387"/>
    <inertia ixx="8.7e-05" iyy="0.008739" izz="0.008786" ixy="-0.0" iyz="1e-06" ixz="0.0"/>
  </inertial>
  <visual>
    <origin xyz="-0.009316 -0.131926 -0.172741" rpy="0 0 0"/>
    <geometry>
      <mesh filename="file://$(find navrover_description)/meshes/left_rocker_arm_1.stl" scale="0.001 0.001 0.001"/>
    </geometry>
    <material name="silver"/>
  </visual>
  <collision>
    <origin xyz="-0.009316 -0.131926 -0.172741" rpy="0 0 0"/>
    <geometry>
      <mesh filename="file://$(find navrover_description)/meshes/left_rocker_arm_1.stl" scale="0.001 0.001 0.001"/>
    </geometry>
  </collision>
</link>

<link name="rover_camera_1">
  <inertial>
    <origin xyz="0.003554697181533076 -2.0100020046076236e-07 0.005792514392210929" rpy="0 0 0"/>
    <mass value="0.002153289793576474"/>
    <inertia ixx="0.0" iyy="0.0" izz="0.0" ixy="-0.0" iyz="-0.0" ixz="-0.0"/>
  </inertial>
  <visual>
    <origin xyz="-0.11748 0.003701 -0.19374" rpy="0 0 0"/>
    <geometry>
      <mesh filename="file://$(find navrover_description)/meshes/rover_camera_1.stl" scale="0.001 0.001 0.001"/>
    </geometry>
    <material name="silver"/>
  </visual>
  <collision>
    <origin xyz="-0.11748 0.003701 -0.19374" rpy="0 0 0"/>
    <geometry>
      <mesh filename="file://$(find navrover_description)/meshes/rover_camera_1.stl" scale="0.001 0.001 0.001"/>
    </geometry>
  </collision>
</link>

<link name="left_rear_motor_1">
  <inertial>
    <origin xyz="-0.0007233464684787139 -0.032863490545547894 -0.06750730161649704" rpy="0 0 0"/>
    <mass value="0.8025906335235503"/>
    <inertia ixx="0.000756" iyy="0.000377" izz="0.000564" ixy="-1.3e-05" iyz="-4.8e-05" ixz="-6.5e-05"/>
  </inertial>
  <visual>
    <origin xyz="0.240684 -0.15026 -0.142476" rpy="0 0 0"/>
    <geometry>
      <mesh filename="file://$(find navrover_description)/meshes/left_rear_motor_1.stl" scale="0.001 0.001 0.001"/>
    </geometry>
    <material name="silver"/>
  </visual>
  <collision>
    <origin xyz="0.240684 -0.15026 -0.142476" rpy="0 0 0"/>
    <geometry>
      <mesh filename="file://$(find navrover_description)/meshes/left_rear_motor_1.stl" scale="0.001 0.001 0.001"/>
    </geometry>
  </collision>
</link>

<link name="right_front_wheel_1">
  <inertial>
    <origin xyz="-2.4480071231791634e-06 -0.05304934910412809 3.45541559178264e-06" rpy="0 0 0"/>
    <mass value="0.10363845671616667"/>
    <inertia ixx="0.000149" iyy="0.000216" izz="0.000149" ixy="0.0" iyz="-0.0" ixz="-0.0"/>
  </inertial>
  <visual>
    <origin xyz="-0.262818 0.165429 -0.062925" rpy="0 0 0"/>
    <geometry>
      <mesh filename="file://$(find navrover_description)/meshes/right_front_wheel_1.stl" scale="0.001 0.001 0.001"/>
    </geometry>
    <material name="silver"/>
  </visual>
  <collision>
    <origin xyz="-0.262818 0.165429 -0.062925" rpy="0 0 0"/>
    <geometry>
      <mesh filename="file://$(find navrover_description)/meshes/right_front_wheel_1.stl" scale="0.001 0.001 0.001"/>
    </geometry>
  </collision>
</link>

<link name="right_rear_wheel_1">
  <inertial>
    <origin xyz="-2.1651424856328205e-06 -0.05305002932436376 3.4614773598007353e-06" rpy="0 0 0"/>
    <mass value="0.10363845671616667"/>
    <inertia ixx="0.000149" iyy="0.000216" izz="0.000149" ixy="0.0" iyz="-0.0" ixz="-0.0"/>
  </inertial>
  <visual>
    <origin xyz="0.245885 0.165394 -0.063543" rpy="0 0 0"/>
    <geometry>
      <mesh filename="file://$(find navrover_description)/meshes/right_rear_wheel_1.stl" scale="0.001 0.001 0.001"/>
    </geometry>
    <material name="silver"/>
  </visual>
  <collision>
    <origin xyz="0.245885 0.165394 -0.063543" rpy="0 0 0"/>
    <geometry>
      <mesh filename="file://$(find navrover_description)/meshes/right_rear_wheel_1.stl" scale="0.001 0.001 0.001"/>
    </geometry>
  </collision>
</link>

<link name="left_front_wheel_1">
  <inertial>
    <origin xyz="1.788549294334807e-06 0.053049405441251946 3.4614773610358585e-06" rpy="0 0 0"/>
    <mass value="0.10363845671616667"/>
    <inertia ixx="0.000149" iyy="0.000216" izz="0.000149" ixy="0.0" iyz="0.0" ixz="0.0"/>
  </inertial>
  <visual>
    <origin xyz="-0.264518 -0.159147 -0.063543" rpy="0 0 0"/>
    <geometry>
      <mesh filename="file://$(find navrover_description)/meshes/left_front_wheel_1.stl" scale="0.001 0.001 0.001"/>
    </geometry>
    <material name="silver"/>
  </visual>
  <collision>
    <origin xyz="-0.264518 -0.159147 -0.063543" rpy="0 0 0"/>
    <geometry>
      <mesh filename="file://$(find navrover_description)/meshes/left_front_wheel_1.stl" scale="0.001 0.001 0.001"/>
    </geometry>
  </collision>
</link>

<link name="left_rear_wheel_1">
  <inertial>
    <origin xyz="2.071413911980402e-06 0.053049725221015476 3.455415590880584e-06" rpy="0 0 0"/>
    <mass value="0.10363845671616667"/>
    <inertia ixx="0.000149" iyy="0.000216" izz="0.000149" ixy="0.0" iyz="0.0" ixz="0.0"/>
  </inertial>
  <visual>
    <origin xyz="0.244185 -0.159181 -0.062925" rpy="0 0 0"/>
    <geometry>
      <mesh filename="file://$(find navrover_description)/meshes/left_rear_wheel_1.stl" scale="0.001 0.001 0.001"/>
    </geometry>
    <material name="silver"/>
  </visual>
  <collision>
    <origin xyz="0.244185 -0.159181 -0.062925" rpy="0 0 0"/>
    <geometry>
      <mesh filename="file://$(find navrover_description)/meshes/left_rear_wheel_1.stl" scale="0.001 0.001 0.001"/>
    </geometry>
  </collision>
</link>

<joint name="left_front_motor_mount_joint" type="fixed">
  <origin xyz="0.25 0.018334 -0.030265" rpy="0 0 0"/>
  <parent link="left_rocker_arm_1"/>
  <child link="left_front_motor_1"/>
</joint>

<joint name="right_rear_motor_mount_joint" type="fixed">
  <origin xyz="-0.25 0.021567 -0.030265" rpy="0 0 0"/>
  <parent link="right_rocker_arm_1"/>
  <child link="right_rear_motor_1"/>
</joint>

<joint name="right_front_motor_mount_joint" type="fixed">
  <origin xyz="0.25 0.021567 -0.030265" rpy="0 0 0"/>
  <parent link="right_rocker_arm_1"/>
  <child link="right_front_motor_1"/>
</joint>

<joint name="right_rocker_arm_joint" type="revolute">
  <origin xyz="0.009316 -0.178074 0.172741" rpy="0 0 0"/>
  <parent link="base_link"/>
  <child link="right_rocker_arm_1"/>
  <axis xyz="0.0 -1.0 0.0"/>
  <limit upper="0.261799" lower="-0.261799" effort="100" velocity="100"/>
</joint>

<joint name="left_rocker_arm_joint" type="revolute">
  <origin xyz="0.009316 0.131926 0.172741" rpy="0 0 0"/>
  <parent link="base_link"/>
  <child link="left_rocker_arm_1"/>
  <axis xyz="0.0 -1.0 0.0"/>
  <limit upper="0.261799" lower="-0.261799" effort="100" velocity="100"/>
</joint>

<joint name="rover_front_camera_joint" type="fixed">
  <origin xyz="0.11748 -0.003701 0.19374" rpy="0 0 0"/>
  <parent link="base_link"/>
  <child link="rover_camera_1"/>
</joint>

<joint name="left_rear_motor_mount_joint" type="fixed">
  <origin xyz="-0.25 0.018334 -0.030265" rpy="0 0 0"/>
  <parent link="left_rocker_arm_1"/>
  <child link="left_rear_motor_1"/>
</joint>

<joint name="right_front_wheel_joint" type="continuous">
  <origin xyz="0.003502 -0.008922 -0.079551" rpy="0 0 0"/>
  <parent link="right_front_motor_1"/>
  <child link="right_front_wheel_1"/>
  <axis xyz="0.0 1.0 0.0"/>
  <limit effort="100" velocity="100"/>
  <dynamics friction="1.0" damping="0.1"/>
</joint>

<joint name="right_rear_wheel_joint" type="continuous">
  <origin xyz="-0.005201 -0.008887 -0.078933" rpy="0 0 0"/>
  <parent link="right_rear_motor_1"/>
  <child link="right_rear_wheel_1"/>
  <axis xyz="0.0 1.0 0.0"/>
  <limit effort="100" velocity="100"/>
  <dynamics friction="1.0" damping="0.1"/>
</joint>

<joint name="left_front_wheel_joint" type="continuous">
  <origin xyz="0.005202 0.008887 -0.078933" rpy="0 0 0"/>
  <parent link="left_front_motor_1"/>
  <child link="left_front_wheel_1"/>
  <axis xyz="0.0 1.0 0.0"/>
  <limit effort="100" velocity="100"/>
  <dynamics friction="1.0" damping="0.1"/>
</joint>

<joint name="left_rear_wheel_joint" type="continuous">
  <origin xyz="-0.003501 0.008921 -0.079551" rpy="0 0 0"/>
  <parent link="left_rear_motor_1"/>
  <child link="left_rear_wheel_1"/>
  <axis xyz="0.0 1.0 0.0"/>
  <limit effort="100" velocity="100"/>
  <dynamics friction="1.0" damping="0.1"/>
</joint>

</robot>
