<?xml version="1.0" ?>
<!-- =================================================================================== -->
<!-- |    This document was autogenerated by xacro from rover.xacro                    | -->
<!-- |    EDITING THIS FILE BY HAND IS NOT RECOMMENDED                                 | -->
<!-- =================================================================================== -->
<robot name="rover">
  <!-- Differential bar mechanism -->
  <gazebo>
    <plugin filename="libleo_gazebo_differential_plugin.so" name="rocker_differential">
      <jointA>left_rocker_joint</jointA>
      <jointB>right_rocker_joint</jointB>
      <forceConstant>50.0</forceConstant>
    </plugin>
  </gazebo>
  <gazebo>
    <plugin filename="libgazebo_ros_control.so" name="gazebo_ros_control">
      <robotNamespace>/rover</robotNamespace>
      <robotSimType>gazebo_ros_control/DefaultRobotHWSim</robotSimType>
      <legacyModeNS>true</legacyModeNS>
    </plugin>
  </gazebo>
  <gazebo>
    <plugin filename="libgazebo_ros_joint_state_publisher.so" name="joint_state_publisher">
      <robotNamespace>/rover</robotNamespace>
      <jointName>wheel_fl_joint, wheel_fr_joint, wheel_rl_joint, wheel_rr_joint, left_rocker_joint, right_rocker_joint</jointName>
      <updateRate>50.0</updateRate>
      <alwaysOn>true</alwaysOn>
    </plugin>
  </gazebo>
  <gazebo>
    <plugin filename="libgazebo_ros_skid_steer_drive.so" name="skid_steer_drive_controller">
      <updateRate>100.0</updateRate>
      <!-- <robotNamespace>/rover</robotNamespace> -->
      <leftFrontJoint>wheel_fl_joint</leftFrontJoint>
      <rightFrontJoint>wheel_fr_joint</rightFrontJoint>
      <leftRearJoint>wheel_rl_joint</leftRearJoint>
      <rightRearJoint>wheel_rr_joint</rightRearJoint>
      <wheelSeparation>0.419308</wheelSeparation>
      <wheelDiameter>0.13</wheelDiameter>
      <robotBaseFrame>base_link</robotBaseFrame>
      <torque>1.736</torque>
      <topicName>cmd_vel</topicName>
      <commandTopic>cmd_vel</commandTopic>
      <broadcastTF>true</broadcastTF>
      <odometryTopic>odom</odometryTopic>
      <odometryFrame>odom</odometryFrame>
      <covariance_x>0.000100</covariance_x>
      <covariance_y>0.000100</covariance_y>
      <covariance_yaw>0.010000</covariance_yaw>
    </plugin>
  </gazebo>
  <gazebo reference="wheel_fl">
    <material>Gazebo/Black</material>
    <mu1>0.8</mu1>
    <mu2>0.8</mu2>
    <kp>1000000.0</kp>
    <kd>100.0</kd>
    <minDepth>0.001</minDepth>
    <maxVel>1.0</maxVel>
  </gazebo>
  <gazebo reference="wheel_fr">
    <material>Gazebo/Black</material>
    <mu1>0.8</mu1>
    <mu2>0.8</mu2>
    <kp>1000000.0</kp>
    <kd>100.0</kd>
    <minDepth>0.001</minDepth>
    <maxVel>1.0</maxVel>
  </gazebo>
  <gazebo reference="wheel_rl">
    <material>Gazebo/Black</material>
    <mu1>0.8</mu1>
    <mu2>0.8</mu2>
    <kp>1000000.0</kp>
    <kd>100.0</kd>
    <minDepth>0.001</minDepth>
    <maxVel>1.0</maxVel>
  </gazebo>
  <gazebo reference="wheel_rr">
    <material>Gazebo/Black</material>
    <mu1>0.8</mu1>
    <mu2>0.8</mu2>
    <kp>1000000.0</kp>
    <kd>100.0</kd>
    <minDepth>0.001</minDepth>
    <maxVel>1.0</maxVel>
  </gazebo>
  <material name="black">
    <color rgba="0.1 0.1 0.1 1"/>
  </material>
  <material name="gray">
    <color rgba="0.5 0.5 0.5 1"/>
  </material>
  <link name="base_link">
    <visual>
      <geometry>
        <box size="0.228 0.178 0.102"/>
      </geometry>
      <material name="black"/>
    </visual>
    <collision>
      <geometry>
        <box size="0.228 0.178 0.102"/>
      </geometry>
    </collision>
    <inertial>
      <origin xyz="0 0 -0.02"/>
      <mass value="5.0"/>
      <inertia ixx="0.0033" ixy="0" ixz="0" iyy="0.0033" iyz="0" izz="0.0033"/>
    </inertial>
  </link>
  <link name="left_rocker">
    <visual>
      <geometry>
        <box size="0.500 0.020 0.040"/>
      </geometry>
      <material name="gray"/>
    </visual>
    <collision>
      <geometry>
        <box size="0.500 0.020 0.040"/>
      </geometry>
    </collision>
    <inertial>
      <origin xyz="0 0 0"/>
      <mass value="0.5"/>
      <inertia ixx="0.00104" ixy="0" ixz="0" iyy="0.01046" iyz="0" izz="0.00948"/>
    </inertial>
  </link>
  <joint name="left_rocker_joint" type="revolute">
    <parent link="base_link"/>
    <child link="left_rocker"/>
    <origin rpy="1.5707963267948966 0 0" xyz="0 0.15 -0.050"/>
    <axis xyz="0 0 1"/>
    <limit effort="100" lower="-0.24" upper="0.24" velocity="100.0"/>
    <dynamics damping="3" friction="1.0"/>
  </joint>
  <link name="right_rocker">
    <visual>
      <geometry>
        <box size="0.500 0.020 0.040"/>
      </geometry>
      <material name="gray"/>
    </visual>
    <collision>
      <geometry>
        <box size="0.500 0.020 0.040"/>
      </geometry>
    </collision>
    <inertial>
      <origin xyz="0 0 0"/>
      <mass value="0.5"/>
      <inertia ixx="0.00104" ixy="0" ixz="0" iyy="0.01046" iyz="0" izz="0.00948"/>
    </inertial>
  </link>
  <joint name="right_rocker_joint" type="revolute">
    <parent link="base_link"/>
    <child link="right_rocker"/>
    <origin rpy="1.5707963267948966 0 0" xyz="0 -0.15 -0.050"/>
    <axis xyz="0 0 1"/>
    <limit effort="100" lower="-0.24" upper="0.24" velocity="100.0"/>
    <dynamics damping="3" friction="1.0"/>
  </joint>
  <link name="motor_fl">
    <visual>
      <geometry>
        <cylinder length="0.080" radius="0.0185"/>
      </geometry>
      <material name="gray"/>
    </visual>
    <collision>
      <geometry>
        <cylinder length="0.080" radius="0.0185"/>
      </geometry>
    </collision>
    <inertial>
      <mass value="0.2"/>
      <inertia ixx="0.00004" ixy="0" ixz="0" iyy="0.00004" iyz="0" izz="0.00002"/>
    </inertial>
  </link>
  <joint name="motor_fl_joint" type="fixed">
    <parent link="left_rocker"/>
    <child link="motor_fl"/>
    <origin rpy="0 0 0" xyz="0.23 -0.15 0"/>
  </joint>
  <link name="motor_fr">
    <visual>
      <geometry>
        <cylinder length="0.080" radius="0.0185"/>
      </geometry>
      <material name="gray"/>
    </visual>
    <collision>
      <geometry>
        <cylinder length="0.080" radius="0.0185"/>
      </geometry>
    </collision>
    <inertial>
      <mass value="0.2"/>
      <inertia ixx="0.00004" ixy="0" ixz="0" iyy="0.00004" iyz="0" izz="0.00002"/>
    </inertial>
  </link>
  <joint name="motor_fr_joint" type="fixed">
    <parent link="right_rocker"/>
    <child link="motor_fr"/>
    <origin rpy="0 0 0" xyz="0.23 -0.15 0"/>
  </joint>
  <link name="motor_rl">
    <visual>
      <geometry>
        <cylinder length="0.080" radius="0.0185"/>
      </geometry>
      <material name="gray"/>
    </visual>
    <collision>
      <geometry>
        <cylinder length="0.080" radius="0.0185"/>
      </geometry>
    </collision>
    <inertial>
      <mass value="0.2"/>
      <inertia ixx="0.00004" ixy="0" ixz="0" iyy="0.00004" iyz="0" izz="0.00002"/>
    </inertial>
  </link>
  <joint name="motor_rl_joint" type="fixed">
    <parent link="left_rocker"/>
    <child link="motor_rl"/>
    <origin rpy="0 0 0" xyz="-0.23 -0.15 0"/>
  </joint>
  <link name="motor_rr">
    <visual>
      <geometry>
        <cylinder length="0.080" radius="0.0185"/>
      </geometry>
      <material name="gray"/>
    </visual>
    <collision>
      <geometry>
        <cylinder length="0.080" radius="0.0185"/>
      </geometry>
    </collision>
    <inertial>
      <mass value="0.2"/>
      <inertia ixx="0.00004" ixy="0" ixz="0" iyy="0.00004" iyz="0" izz="0.00002"/>
    </inertial>
  </link>
  <joint name="motor_rr_joint" type="fixed">
    <parent link="right_rocker"/>
    <child link="motor_rr"/>
    <origin rpy="0 0 0" xyz="-0.23 -0.15 0"/>
  </joint>
  <link name="wheel_fl">
    <visual>
      <geometry>
        <cylinder length="0.058785" radius="0.065"/>
      </geometry>
      <material name="black"/>
    </visual>
    <collision>
      <geometry>
        <cylinder length="0.058785" radius="0.065"/>
      </geometry>
      <surface>
        <friction>
          <ode>
            <mu>1</mu>
            <mu2>1</mu2>
          </ode>
        </friction>
      </surface>
    </collision>
    <inertial>
      <mass value="0.5"/>
      <inertia ixx="0.00032" ixy="0" ixz="0" iyy="0.00032" iyz="0" izz="0.00063"/>
    </inertial>
  </link>
  <joint name="wheel_fl_joint" type="continuous">
    <parent link="motor_fl"/>
    <child link="wheel_fl"/>
    <origin rpy="0 0 0" xyz="0 0 -0.07"/>
    <axis xyz="0 0 1"/>
    <limit effort="2.0" velocity="6.0"/>
    <dynamics damping="0.1" friction="0.3125"/>
  </joint>
  <link name="wheel_fr">
    <visual>
      <geometry>
        <cylinder length="0.058785" radius="0.065"/>
      </geometry>
      <material name="black"/>
    </visual>
    <collision>
      <geometry>
        <cylinder length="0.058785" radius="0.065"/>
      </geometry>
      <surface>
        <friction>
          <ode>
            <mu>1</mu>
            <mu2>1</mu2>
          </ode>
        </friction>
      </surface>
    </collision>
    <inertial>
      <mass value="0.5"/>
      <inertia ixx="0.00032" ixy="0" ixz="0" iyy="0.00032" iyz="0" izz="0.00063"/>
    </inertial>
  </link>
  <joint name="wheel_fr_joint" type="continuous">
    <parent link="motor_fr"/>
    <child link="wheel_fr"/>
    <origin rpy="0 0 0" xyz="0 0 0.07"/>
    <axis xyz="0 0 1"/>
    <limit effort="2.0" velocity="6.0"/>
    <dynamics damping="0.1" friction="0.3125"/>
  </joint>
  <link name="wheel_rl">
    <visual>
      <geometry>
        <cylinder length="0.058785" radius="0.065"/>
      </geometry>
      <material name="black"/>
    </visual>
    <collision>
      <geometry>
        <cylinder length="0.058785" radius="0.065"/>
      </geometry>
      <surface>
        <friction>
          <ode>
            <mu>1</mu>
            <mu2>1</mu2>
          </ode>
        </friction>
      </surface>
    </collision>
    <inertial>
      <mass value="0.5"/>
      <inertia ixx="0.00032" ixy="0" ixz="0" iyy="0.00032" iyz="0" izz="0.00063"/>
    </inertial>
  </link>
  <joint name="wheel_rl_joint" type="continuous">
    <parent link="motor_rl"/>
    <child link="wheel_rl"/>
    <origin rpy="0 0 0" xyz="0 0 -0.07"/>
    <axis xyz="0 0 1"/>
    <limit effort="2.0" velocity="6.0"/>
    <dynamics damping="0.1" friction="0.3125"/>
  </joint>
  <link name="wheel_rr">
    <visual>
      <geometry>
        <cylinder length="0.058785" radius="0.065"/>
      </geometry>
      <material name="black"/>
    </visual>
    <collision>
      <geometry>
        <cylinder length="0.058785" radius="0.065"/>
      </geometry>
      <surface>
        <friction>
          <ode>
            <mu>1</mu>
            <mu2>1</mu2>
          </ode>
        </friction>
      </surface>
    </collision>
    <inertial>
      <mass value="0.5"/>
      <inertia ixx="0.00032" ixy="0" ixz="0" iyy="0.00032" iyz="0" izz="0.00063"/>
    </inertial>
  </link>
  <joint name="wheel_rr_joint" type="continuous">
    <parent link="motor_rr"/>
    <child link="wheel_rr"/>
    <origin rpy="0 0 0" xyz="0 0 0.07"/>
    <axis xyz="0 0 1"/>
    <limit effort="2.0" velocity="6.0"/>
    <dynamics damping="0.1" friction="0.3125"/>
  </joint>
  <!-- Differential bar -->
  <link name="differential_bar">
    <visual>
      <geometry>
        <box size="0.45 0.02 0.02"/>
      </geometry>
      <material name="gray"/>
    </visual>
    <collision>
      <geometry>
        <box size="0.45 0.02 0.02"/>
      </geometry>
    </collision>
    <inertial>
      <mass value="0.1"/>
      <inertia ixx="0.0001" ixy="0" ixz="0" iyy="0.0001" iyz="0" izz="0.0001"/>
    </inertial>
  </link>
  <joint name="differential_bar_joint" type="revolute">
    <parent link="base_link"/>
    <child link="differential_bar"/>
    <origin rpy="0 0 0" xyz="0 0 0.06"/>
    <axis xyz="0 1 0"/>
    <limit effort="10" lower="-0.5" upper="0.5" velocity="1.0"/>
  </joint>
  <link name="left_differential_mount">
    <visual>
      <geometry>
        <box size="0.02 0.02 0.02"/>
      </geometry>
      <material name="gray"/>
    </visual>
    <collision>
      <geometry>
        <box size="0.02 0.02 0.02"/>
      </geometry>
    </collision>
    <inertial>
      <mass value="0.1"/>
      <inertia ixx="0.0001" ixy="0" ixz="0" iyy="0.0001" iyz="0" izz="0.0001"/>
    </inertial>
  </link>
  <joint name="left_differential_mount_joint" type="fixed">
    <parent link="left_rocker"/>
    <child link="left_differential_mount"/>
    <origin rpy="0 0 0" xyz="0.25 0.05 0.02"/>
  </joint>
  <joint name="left_differential_bar_joint" type="revolute">
    <parent link="differential_bar"/>
    <child link="left_differential_mount"/>
    <origin rpy="0 0 0" xyz="0.225 0 0"/>
    <axis xyz="0 1 0"/>
    <limit effort="10" lower="-0.1" upper="0.1" velocity="1.0"/>
  </joint>
  <link name="right_differential_mount">
    <visual>
      <geometry>
        <box size="0.02 0.02 0.02"/>
      </geometry>
      <material name="gray"/>
    </visual>
    <collision>
      <geometry>
        <box size="0.02 0.02 0.02"/>
      </geometry>
    </collision>
    <inertial>
      <mass value="0.1"/>
      <inertia ixx="0.0001" ixy="0" ixz="0" iyy="0.0001" iyz="0" izz="0.0001"/>
    </inertial>
  </link>
  <joint name="right_differential_mount_joint" type="fixed">
    <parent link="right_rocker"/>
    <child link="right_differential_mount"/>
    <origin rpy="0 0 0" xyz="0.25 -0.05 0.02"/>
  </joint>
  <joint name="right_differential_bar_joint" type="revolute">
    <parent link="differential_bar"/>
    <child link="right_differential_mount"/>
    <origin rpy="0 0 0" xyz="-0.225 0 0"/>
    <axis xyz="0 1 0"/>
    <limit effort="10" lower="-0.1" upper="0.1" velocity="1.0"/>
  </joint>
  <!-- Transmissions for ros_control -->
  <transmission name="left_rocker_trans">
    <type>transmission_interface/SimpleTransmission</type>
    <joint name="left_rocker_joint">
      <hardwareInterface>hardware_interface/EffortJointInterface</hardwareInterface>
    </joint>
    <actuator name="left_rocker_motor">
      <hardwareInterface>hardware_interface/EffortJointInterface</hardwareInterface>
      <mechanicalReduction>1</mechanicalReduction>
    </actuator>
  </transmission>
  <transmission name="right_rocker_trans">
    <type>transmission_interface/SimpleTransmission</type>
    <joint name="right_rocker_joint">
      <hardwareInterface>hardware_interface/EffortJointInterface</hardwareInterface>
    </joint>
    <actuator name="right_rocker_motor">
      <hardwareInterface>hardware_interface/EffortJointInterface</hardwareInterface>
      <mechanicalReduction>1</mechanicalReduction>
    </actuator>
  </transmission>
</robot>
