<?xml version="1.0"?>
<robot xmlns:xacro="http://www.ros.org/wiki/xacro" name="rover">

  <xacro:include filename="$(find navrover_simulation)/urdf/rover.gazebo" />  
  <xacro:include filename="$(find navrover_simulation)/urdf/kinect_sensor.xacro" />
  <xacro:property name="PI" value="3.1415926535897931"/>
  
  <xacro:macro name="default_inertial" params="mass">
    <inertial>
      <mass value="${mass}"/>
      <inertia ixx="1.0" ixy="0.0" ixz="0.0" iyy="1.0" iyz="0.0" izz="1.0"/>
    </inertial>
  </xacro:macro>

  <material name="black">
    <color rgba="0.1 0.1 0.1 1"/>
  </material>
  <material name="gray">
    <color rgba="0.5 0.5 0.5 1"/>
  </material>

  <material name="white">
    <color rgba="1 1 1 1"/>
  </material>  

  <!--New base_footprint link -->
  <link name="base_footprint"/>


  <!-- New joint between base_footprint and base_link -->
  <joint name="base_joint" type="fixed">
    <parent link="base_footprint"/>
    <child link="base_link"/>
    <origin xyz="0 0 0.22" rpy="0 0 0"/>
  </joint>

  <!-- Base Link -->
  <link name="base_link">
    <visual>
      <origin xyz="0 0 0.051" rpy="0 0 ${PI}"/>
      <geometry>
        <box size="0.228 0.178 0.102"/>
      </geometry>
      <material name="white"/>
    </visual>
    <collision>
      <origin xyz="0 0 0.051" rpy="0 0 ${PI}"/>
      <geometry>
        <box size="0.228 0.178 0.102"/>
      </geometry>
    </collision>
    <inertial>
      <origin xyz="-0.005 0 0.031" rpy="0 0 ${PI}"/>
      <mass value="5.0"/>
      <inertia ixx="0.0033" ixy="0" ixz="0" iyy="0.0033" iyz="0" izz="0.0033"/>
    </inertial>
  </link>

  <!-- Lidar Mount Link -->
  <link name="lidar_mount">
    <visual>
      <origin xyz="0 0 0.01" rpy="0 0 ${PI}"/>
      <geometry>
        <box size="0.06 0.06 0.02"/>
      </geometry>
      <material name="gray"/>
    </visual>
    <collision>
      <origin xyz="0 0 0.0192" rpy="0 0 ${PI}"/>
      <geometry>
        <box size="0.06 0.06 0.02"/>
      </geometry>
    </collision>
    <inertial>
      <mass value="0.05"/>
      <inertia ixx="0.0001" ixy="0" ixz="0" iyy="0.0001" iyz="0" izz="0.0001"/>
    </inertial>
  </link>

  <!-- Lidar Mount Joint -->
  <joint name="lidar_mount_joint" type="fixed">
    <parent link="base_link"/>
    <child link="lidar_mount"/>
    <origin xyz="0.07 0 0.102" rpy="0 0 ${PI}"/>
  </joint>

  <!-- Lidar Link -->
  <link name="lidar_link">
    <visual>
      <origin xyz="0 0 0.0205" rpy="0 0 ${PI}"/>
      <geometry>
        <cylinder radius="0.0375" length="0.041"/>
      </geometry>
      <material name="black"/>
    </visual>
    <collision>
      <origin xyz="0 0 0.0205" rpy="0 0 ${PI}"/>
      <geometry>
        <cylinder radius="0.0375" length="0.041"/>
      </geometry>
    </collision>
    <inertial>
      <mass value="0.19"/>
      <inertia ixx="0.0001" ixy="0" ixz="0" iyy="0.0001" iyz="0" izz="0.0001"/>
    </inertial>
  </link>

  <!-- Lidar Joint -->
  <joint name="lidar_joint" type="fixed">
    <parent link="lidar_mount"/>
    <child link="lidar_link"/>
    <origin xyz="0 0 0.02" rpy="0 0 0"/>
  </joint>

    <!-- Depth Camera Mount Link -->
  <link name="depth_camera_mount">
    <visual>
      <origin xyz="0 0 0.125" rpy="0 0 0"/>
      <geometry>
        <cylinder radius="0.02" length="0.25"/>
      </geometry>
      <material name="gray"/>
    </visual>
    <collision>
      <origin xyz="0 0 0.125" rpy="0 0 0"/>
      <geometry>
        <cylinder radius="0.02" length="0.25"/>
      </geometry>
    </collision>
    <inertial>
      <mass value="0.1"/>
      <inertia ixx="0.000208" ixy="0" ixz="0" iyy="0.000208" iyz="0" izz="0.00002"/>
    </inertial>
  </link>

  <!-- Depth Camera Mount Joint -->
  <joint name="depth_camera_mount_joint" type="fixed">
    <parent link="base_link"/>
    <child link="depth_camera_mount"/>
    <origin xyz="0 0 0.102" rpy="0 0 0"/>
  </joint>

  <xacro:sensor_kinect parent="depth_camera_mount" />

    <!-- Camera Link -->
  <link name="camera_link">
    <visual>
      <origin xyz="0 0 0" rpy="0 0 ${PI}"/>
      <geometry>
        <box size="0.02 0.03 0.03"/>
      </geometry>
      <material name="gray"/>
    </visual>
    <collision>
      <origin xyz="0 0 0" rpy="0 0 ${PI}"/>
      <geometry>
        <box size="0.03 0.03 0.03"/>
      </geometry>
    </collision>
    <inertial>
      <mass value="0.1"/>
      <inertia ixx="0.0001" ixy="0" ixz="0" iyy="0.0001" iyz="0" izz="0.0001"/>
    </inertial>
  </link>

  <!-- Camera Joint -->
  <joint name="camera_joint" type="fixed">
    <parent link="base_link"/>
    <child link="camera_link"/>
    <origin xyz="0.114 0 0.05" rpy="0 0 0"/>
  </joint>

  <xacro:macro name="rocker" params="prefix reflect">
    <link name="${prefix}_rocker">
      <visual>
        <geometry>
          <box size="0.500 0.020 0.040"/>
        </geometry>
        <material name="gray"/>
      </visual>
      <collision>
        <geometry>
          <box size="0.500 0.020 0.040"/>
        </geometry>
      </collision>
      <inertial>
        <origin xyz="0 0 0"/>
        <mass value="0.5"/>
        <inertia ixx="0.00104" ixy="0" ixz="0" iyy="0.01046" iyz="0" izz="0.00948"/>
      </inertial>
    </link>

    <joint name="${prefix}_rocker_joint" type="revolute">
      <parent link="base_link"/>
      <child link="${prefix}_rocker"/>
      <origin xyz="0 ${reflect * -0.15} 0.001" rpy="${PI/2} 0 0"/>
      <axis xyz="0 0 1"/>
      <limit lower="-0.24" upper="0.24" effort="100" velocity="100.0"/>
      <dynamics friction="1.0" damping="0.1"/>
    </joint>
  </xacro:macro>

  <xacro:rocker prefix="left" reflect="1"/>
  <xacro:rocker prefix="right" reflect="-1"/>

  <xacro:macro name="motor" params="prefix parent_link x_pos y_pos z_pos">
    <link name="motor_${prefix}">
      <visual>
        <geometry>
          <cylinder radius="0.0185" length="0.080"/>
        </geometry>
        <material name="gray"/>
      </visual>
      <collision>
        <geometry>
          <cylinder radius="0.0185" length="0.080"/>
        </geometry>
      </collision>
      <inertial>
        <mass value="0.2"/>
        <inertia ixx="0.00004" ixy="0" ixz="0" iyy="0.00004" iyz="0" izz="0.00002"/>
      </inertial>
    </link>

    <joint name="motor_${prefix}_joint" type="fixed">
      <parent link="${parent_link}"/>
      <child link="motor_${prefix}"/>
      <origin xyz="${x_pos} ${y_pos} ${z_pos}" rpy="0 0 0"/>
    </joint>
  </xacro:macro>

  <xacro:motor prefix="rl" parent_link="left_rocker" x_pos="-0.230" y_pos="-0.15" z_pos="0"/>
  <xacro:motor prefix="rr" parent_link="right_rocker" x_pos="-0.230" y_pos="-0.15" z_pos="0"/>
  <xacro:motor prefix="fl" parent_link="left_rocker" x_pos="0.230" y_pos="-0.15" z_pos="0"/>
  <xacro:motor prefix="fr" parent_link="right_rocker" x_pos="0.230" y_pos="-0.15" z_pos="0"/>


  <xacro:macro name="wheel" params="prefix parent_link z_offset">
    <link name="wheel_${prefix}">
      <visual>
        <geometry>
          <cylinder radius="0.065" length="0.058785"/>
        </geometry>
        <material name="black"/>
      </visual>
      <collision>
        <geometry>https://github.com/jj7258/NavRover.git
          <cylinder radius="0.065" length="0.058785"/>
        </geometry>
      </collision>
      <inertial>
        <mass value="0.5"/>
        <inertia ixx="0.00032" ixy="0" ixz="0" iyy="0.00032" iyz="0" izz="0.00063"/>
      </inertial>
    </link>

    <joint name="wheel_${prefix}_joint" type="continuous">
      <parent link="${parent_link}"/>
      <child link="wheel_${prefix}"/>
      <origin xyz="0 0 ${z_offset}" rpy="${PI} 0 0"/>
      <axis xyz="0 0 1"/>
      <limit effort="2.0" velocity="6.0"/>
      <dynamics friction="0.3125" damping="0.1"/>
    </joint>
  </xacro:macro>

  <xacro:wheel prefix="fl" parent_link="motor_fl" z_offset="0.07"/>
  <xacro:wheel prefix="fr" parent_link="motor_fr" z_offset="-0.07"/>
  <xacro:wheel prefix="rl" parent_link="motor_rl" z_offset="0.07"/>
  <xacro:wheel prefix="rr" parent_link="motor_rr" z_offset="-0.07"/>

  <!-- Transmissions for ros_control -->
  <transmission name="left_rocker_trans">
    <type>transmission_interface/SimpleTransmission</type>
    <joint name="left_rocker_joint">
      <hardwareInterface>hardware_interface/EffortJointInterface</hardwareInterface>
    </joint>
    <actuator name="left_rocker_motor">
      <hardwareInterface>hardware_interface/EffortJointInterface</hardwareInterface>
      <mechanicalReduction>1</mechanicalReduction>
    </actuator>
  </transmission>

  <transmission name="right_rocker_trans">
    <type>transmission_interface/SimpleTransmission</type>
    <joint name="right_rocker_joint">
      <hardwareInterface>hardware_interface/EffortJointInterface</hardwareInterface>
    </joint>
    <actuator name="right_rocker_motor">
      <hardwareInterface>hardware_interface/EffortJointInterface</hardwareInterface>
      <mechanicalReduction>1</mechanicalReduction>
    </actuator>
  </transmission>

</robot>



